<mujoco model="base">
  <compiler angle="radian" meshdir="meshes/" autolimits="true"/>
  <option impratio="20" density="1.2" viscosity="2e-05" cone="elliptic"/>
  <size njmax="5000" nconmax="5000"/>
  <visual>
    <map znear="0.001"/>
  </visual>
  <statistic meansize="0.171899" extent="10.6098" center="1.11639 0 1.5"/>
  <asset>
    <texture type="skybox" builtin="gradient" rgb1="0.9 0.9 1" rgb2="0.2 0.3 0.4" width="256" height="1536"/>
    <texture type="2d" name="texplane" file="/home/lorangpi/Enigma/robosuite/src/robosuite/models/assets/arenas/../textures/light-gray-floor-tile.png"/>
    <texture type="cube" name="tex-ceramic" file="/home/lorangpi/Enigma/robosuite/src/robosuite/models/assets/arenas/../textures/ceramic.png"/>
    <texture type="cube" name="tex-steel-brushed" file="/home/lorangpi/Enigma/robosuite/src/robosuite/models/assets/arenas/../textures/steel-brushed.png"/>
    <texture type="2d" name="tex-light-gray-plaster" file="/home/lorangpi/Enigma/robosuite/src/robosuite/models/assets/arenas/../textures/light-gray-plaster.png"/>
    <texture type="cube" name="textable" builtin="flat" rgb1="0.5 0.5 0.5" width="512" height="3072"/>
    <texture type="cube" name="cube_bread_bread" file="/home/lorangpi/Enigma/robosuite/src/robosuite/models/assets/textures/bread.png"/>
    <texture type="cube" name="PotObject_steel_scratched_tex" file="/home/lorangpi/Enigma/robosuite/src/robosuite/models/assets/textures/steel-scratched.png"/>
    <texture type="cube" name="Button1_darkwood" file="/home/lorangpi/Enigma/robosuite/src/robosuite/models/assets/textures/dark-wood.png"/>
    <texture type="cube" name="Button1_metal" file="/home/lorangpi/Enigma/robosuite/src/robosuite/models/assets/textures/metal.png"/>
    <texture type="cube" name="Button1_redwood" file="/home/lorangpi/Enigma/robosuite/src/robosuite/models/assets/textures/red-wood.png"/>
    <texture type="cube" name="Stove1_darkwood" file="/home/lorangpi/Enigma/robosuite/src/robosuite/models/assets/textures/dark-wood.png"/>
    <texture type="cube" name="Stove1_metal" file="/home/lorangpi/Enigma/robosuite/src/robosuite/models/assets/textures/metal.png"/>
    <texture type="cube" name="Stove1_redwood" file="/home/lorangpi/Enigma/robosuite/src/robosuite/models/assets/textures/red-wood.png"/>
    <texture type="cube" name="ServingRegionRed_darkwood" file="/home/lorangpi/Enigma/robosuite/src/robosuite/models/assets/textures/dark-wood.png"/>
    <texture type="cube" name="ServingRegionRed_metal" file="/home/lorangpi/Enigma/robosuite/src/robosuite/models/assets/textures/metal.png"/>
    <texture type="cube" name="ServingRegionRed_redwood" file="/home/lorangpi/Enigma/robosuite/src/robosuite/models/assets/textures/red-wood.png"/>
    <material name="floorplane" texture="texplane" texuniform="true" texrepeat="2 2" specular="0" shininess="0" reflectance="0.01"/>
    <material name="table_ceramic" texture="tex-ceramic" specular="0.2" shininess="0"/>
    <material name="table_legs_metal" texture="tex-steel-brushed" shininess="0.8" reflectance="0.8"/>
    <material name="walls_mat" texture="tex-light-gray-plaster" texuniform="true" texrepeat="3 3" specular="0.1" shininess="0.1"/>
    <material name="table_mat" texture="textable"/>
    <material name="cube_bread_MatBread" texture="cube_bread_bread" texrepeat="3 3" specular="0.4" shininess="0.1"/>
    <material name="PotObject_steel_scratched_mat" texture="PotObject_steel_scratched_tex" texrepeat="3 3" specular="0.4" shininess="0.1"/>
    <material name="Button1_MatDarkWood" texture="Button1_darkwood" texrepeat="3 3" specular="0.4" shininess="0.1"/>
    <material name="Button1_MatMetal" texture="Button1_metal" specular="1" shininess="0.3" rgba="0.9 0.9 0.9 1"/>
    <material name="Button1_MatRedWood" texture="Button1_redwood" specular="0.4" shininess="0.1"/>
    <material name="Stove1_MatDarkWood" texture="Stove1_darkwood" texrepeat="3 3" specular="0.4" shininess="0.1"/>
    <material name="Stove1_MatMetal" texture="Stove1_metal" specular="1" shininess="0.3" rgba="0.9 0.9 0.9 1"/>
    <material name="Stove1_MatRedWood" texture="Stove1_redwood" specular="0.4" shininess="0.1"/>
    <material name="ServingRegionRed_MatDarkWood" texture="ServingRegionRed_darkwood" texrepeat="3 3" specular="0.4" shininess="0.1"/>
    <material name="ServingRegionRed_MatMetal" texture="ServingRegionRed_metal" specular="1" shininess="0.3" rgba="0.9 0.9 0.9 1"/>
    <material name="ServingRegionRed_MatRedWood" texture="ServingRegionRed_redwood" specular="0.4" shininess="0.1"/>
    <mesh name="robot0_base_link" file="/home/lorangpi/Enigma/robosuite/src/robosuite/models/assets/robots/kinova3/meshes/base_link.stl"/>
    <mesh name="robot0_shoulder_link" file="/home/lorangpi/Enigma/robosuite/src/robosuite/models/assets/robots/kinova3/meshes/shoulder_link.stl"/>
    <mesh name="robot0_half_arm_1_link" file="/home/lorangpi/Enigma/robosuite/src/robosuite/models/assets/robots/kinova3/meshes/half_arm_1_link.stl"/>
    <mesh name="robot0_half_arm_2_link" file="/home/lorangpi/Enigma/robosuite/src/robosuite/models/assets/robots/kinova3/meshes/half_arm_2_link.stl"/>
    <mesh name="robot0_forearm_link" file="/home/lorangpi/Enigma/robosuite/src/robosuite/models/assets/robots/kinova3/meshes/forearm_link.stl"/>
    <mesh name="robot0_spherical_wrist_1_link" file="/home/lorangpi/Enigma/robosuite/src/robosuite/models/assets/robots/kinova3/meshes/spherical_wrist_1_link.stl"/>
    <mesh name="robot0_spherical_wrist_2_link" file="/home/lorangpi/Enigma/robosuite/src/robosuite/models/assets/robots/kinova3/meshes/spherical_wrist_2_link.stl"/>
    <mesh name="robot0_bracelet_with_vision_link" file="/home/lorangpi/Enigma/robosuite/src/robosuite/models/assets/robots/kinova3/meshes/bracelet_with_vision_link.stl"/>
    <mesh name="mount0_pedestal" file="/home/lorangpi/Enigma/robosuite/src/robosuite/models/assets/mounts/meshes/rethink_mount/pedestal.stl"/>
    <mesh name="gripper0_robotiq_arg2f_base_link" file="/home/lorangpi/Enigma/robosuite/src/robosuite/models/assets/grippers/meshes/robotiq_85_gripper/robotiq_arg2f_base_link.stl"/>
    <mesh name="gripper0_robotiq_arg2f_85_outer_knuckle" file="/home/lorangpi/Enigma/robosuite/src/robosuite/models/assets/grippers/meshes/robotiq_85_gripper/robotiq_arg2f_85_outer_knuckle.stl" scale="0.001 0.001 0.001"/>
    <mesh name="gripper0_robotiq_arg2f_85_outer_finger" file="/home/lorangpi/Enigma/robosuite/src/robosuite/models/assets/grippers/meshes/robotiq_85_gripper/robotiq_arg2f_85_outer_finger.stl" scale="0.001 0.001 0.001"/>
    <mesh name="gripper0_robotiq_arg2f_85_inner_finger" file="/home/lorangpi/Enigma/robosuite/src/robosuite/models/assets/grippers/meshes/robotiq_85_gripper/robotiq_arg2f_85_inner_finger.stl" scale="0.001 0.001 0.001"/>
    <mesh name="gripper0_robotiq_arg2f_85_inner_knuckle" file="/home/lorangpi/Enigma/robosuite/src/robosuite/models/assets/grippers/meshes/robotiq_85_gripper/robotiq_arg2f_85_inner_knuckle.stl" scale="0.001 0.001 0.001"/>
    <mesh name="gripper0_robotiq_arg2f_85_outer_knuckle_vis" file="/home/lorangpi/Enigma/robosuite/src/robosuite/models/assets/grippers/meshes/robotiq_85_gripper/robotiq_arg2f_85_outer_knuckle_vis.stl" scale="0.001 0.001 0.001"/>
    <mesh name="gripper0_robotiq_arg2f_85_outer_finger_vis" file="/home/lorangpi/Enigma/robosuite/src/robosuite/models/assets/grippers/meshes/robotiq_85_gripper/robotiq_arg2f_85_outer_finger_vis.stl" scale="0.001 0.001 0.001"/>
    <mesh name="gripper0_robotiq_arg2f_85_inner_finger_vis" file="/home/lorangpi/Enigma/robosuite/src/robosuite/models/assets/grippers/meshes/robotiq_85_gripper/robotiq_arg2f_85_inner_finger_vis.stl" scale="0.001 0.001 0.001"/>
    <mesh name="gripper0_robotiq_arg2f_85_inner_knuckle_vis" file="/home/lorangpi/Enigma/robosuite/src/robosuite/models/assets/grippers/meshes/robotiq_85_gripper/robotiq_arg2f_85_inner_knuckle_vis.stl" scale="0.001 0.001 0.001"/>
    <mesh name="Stove1_burnerplate" file="/home/lorangpi/CyclicLxM/robosuite-task-zoo/robosuite_task_zoo/models/kitchen/./burnerplate.stl" scale="0.55 0.55 0.45"/>
  </asset>
  <worldbody>
    <geom name="floor" size="3 3 0.125" type="plane" group="1" material="floorplane"/>
    <geom name="wall_leftcorner_visual" size="1.06 1.5 0.01" pos="-1.25 2.25 1.5" quat="0.653281 0.653281 0.270598 0.270598" type="box" contype="0" conaffinity="0" group="1" material="walls_mat"/>
    <geom name="wall_rightcorner_visual" size="1.06 1.5 0.01" pos="-1.25 -2.25 1.5" quat="0.653281 0.653281 -0.270598 -0.270598" type="box" contype="0" conaffinity="0" group="1" material="walls_mat"/>
    <geom name="wall_left_visual" size="1.75 1.5 0.01" pos="1.25 3 1.5" quat="0.707107 0.707107 0 0" type="box" contype="0" conaffinity="0" group="1" material="walls_mat"/>
    <geom name="wall_right_visual" size="1.75 1.5 0.01" pos="1.25 -3 1.5" quat="0.707107 -0.707107 0 0" type="box" contype="0" conaffinity="0" group="1" material="walls_mat"/>
    <geom name="wall_rear_visual" size="1.5 1.5 0.01" pos="-2 0 1.5" quat="0.5 0.5 0.5 0.5" type="box" contype="0" conaffinity="0" group="1" material="walls_mat"/>
    <geom name="wall_front_visual" size="3 1.5 0.01" pos="3 0 1.5" quat="0.5 0.5 -0.5 -0.5" type="box" contype="0" conaffinity="0" group="1" material="walls_mat"/>
    <camera name="frontview" pos="1.6 0 1.45" quat="0.560842 0.430646 0.430646 0.560842"/>
    <camera name="birdview" pos="-0.2 0 3" quat="0.707107 0 0 0.707107"/>
    <camera name="agentview" pos="0.538613 -4.39204e-09 1.49035" quat="0.638018 0.30485 0.30485 0.638018"/>
    <camera name="sideview" pos="0.558613 0.3 1.29035" quat="0.414423 0.310092 0.496415 0.696899"/>
    <light pos="1 1 1.5" dir="-0.19245 -0.19245 -0.96225" directional="true" castshadow="false"/>
    <body name="table" pos="-0.2 0 0.875">
      <geom name="table_collision" size="0.5 0.4 0.025" type="box" friction="0.6 0.005 0.0001" rgba="0.5 0.5 0 1"/>
      <geom name="table_visual" size="0.5 0.4 0.025" type="box" contype="0" conaffinity="0" group="1" material="table_ceramic"/>
      <geom name="table_leg1_visual" size="0.025 0.4375" pos="0.4 0.3 -0.4375" type="cylinder" contype="0" conaffinity="0" group="1" material="table_legs_metal"/>
      <geom name="table_leg2_visual" size="0.025 0.4375" pos="-0.4 0.3 -0.4375" type="cylinder" contype="0" conaffinity="0" group="1" material="table_legs_metal"/>
      <geom name="table_leg3_visual" size="0.025 0.4375" pos="-0.4 -0.3 -0.4375" type="cylinder" contype="0" conaffinity="0" group="1" material="table_legs_metal"/>
      <geom name="table_leg4_visual" size="0.025 0.4375" pos="0.4 -0.3 -0.4375" type="cylinder" contype="0" conaffinity="0" group="1" material="table_legs_metal"/>
      <site name="table_top" pos="0 0 0.025" size="0.001" rgba="0 0 0 0"/>
      <body name="Stove1_main" pos="0 0.195 0.02">
        <site name="Stove1_default_site" pos="0 0 0" size="0.002" rgba="1 0 0 0"/>
        <body name="Stove1_base">
          <geom name="Stove1_base" size="0.095 0.095 0.02" type="box" group="1" material="Stove1_MatMetal"/>
          <geom name="Stove1_collision_burner" size="0.095 0.095 0.0005" pos="0 0 0.022" type="box" group="1" rgba="0 0 0 0"/>
          <site name="Stove1_burner_on" pos="0 0 0.022" size="0.0625 0.0005" type="cylinder" rgba="1 0 0 1"/>
          <body name="Stove1_burner">
            <geom name="Stove1_burner" pos="0 0 0.025" type="mesh" contype="0" conaffinity="0" group="1" material="Stove1_MatMetal" mesh="Stove1_burnerplate"/>
          </body>
        </body>
      </body>
      <body name="Button1_main" pos="-0.2 0.1 0.02" quat="0 0 0 1">
        <site name="Button1_default_site" pos="0 0 0" size="0.002" rgba="1 0 0 0"/>
        <body name="Button1_base">
          <geom name="Button1_base" size="0.04 0.02" type="cylinder" group="1" material="Button1_MatMetal"/>
          <body name="Button1_switch">
            <inertial pos="0.0296816 -0.00152345 0" quat="0.701072 0 0 0.713091" mass="0.243455" diaginertia="0.0913751 0.0521615 0.043714"/>
            <joint name="Button1_hinge" pos="0 0 0.03" axis="1 0 0" range="-0.3 0.3" damping="0.1" frictionloss="0.1"/>
            <geom name="Button1_switch" size="0.025 0.007 0.025" pos="0 0 0.05" type="box" group="1" material="Button1_MatMetal"/>
            <geom name="Button1_switch_pad" size="0.0325 0.0125" pos="0 0 0.08" quat="0 0 0.701072 0.713091" type="cylinder" group="1" material="Button1_MatMetal"/>
          </body>
        </body>
      </body>
      <body name="ServingRegionRed_main" pos="0.09 -0.15 0.003">
        <site name="ServingRegionRed_default_site" pos="0 0 0" size="0.002" rgba="1 0 0 0"/>
        <body name="ServingRegionRed_base">
          <site name="ServingRegionRed_plate" pos="0 0 0.022" size="0.07 0.1 0.001" type="box" material="ServingRegionRed_MatRedWood" rgba="1 0 0 1"/>
        </body>
      </body>
    </body>
    <body name="robot0_base" pos="-0.66 0 0.912">
      <inertial pos="0 0 0" mass="0" diaginertia="0 0 0"/>
      <geom name="robot0_g0_vis" type="mesh" contype="0" conaffinity="0" group="1" rgba="1 1 1 1" mesh="robot0_base_link"/>
      <geom name="robot0_base_collision" type="mesh" conaffinity="0" rgba="0 0.5 0 1" mesh="robot0_base_link"/>
      <camera name="robot0_robotview" pos="1 0 0.4" quat="0.653098 0.271041 0.271041 0.653098"/>
      <body name="robot0_shoulder_link" pos="0 0 0.15643" quat="-3.67321e-06 1 0 0">
        <inertial pos="-2.3e-05 -0.010364 -0.07336" quat="0.707051 0.0451246 -0.0453544 0.704263" mass="1.3773" diaginertia="0.00488868 0.00457 0.00135132"/>
        <joint name="robot0_Actuator1" pos="0 0 0" axis="0 0 1" armature="5" damping="0.1" frictionloss="0.1"/>
        <geom name="robot0_s_visual" type="mesh" contype="0" conaffinity="0" group="1" rgba="1 1 1 1" mesh="robot0_shoulder_link"/>
        <geom name="robot0_s_collision" type="mesh" conaffinity="0" rgba="0 0.5 0 1" mesh="robot0_shoulder_link"/>
        <body name="robot0_HalfArm1_Link" pos="0 0.005375 -0.12838" quat="0.707105 0.707108 0 0">
          <inertial pos="-4.4e-05 -0.09958 -0.013278" quat="0.482348 0.516286 -0.516862 0.483366" mass="1.1636" diaginertia="0.0113017 0.011088 0.00102532"/>
          <joint name="robot0_Actuator2" pos="0 0 0" axis="0 0 1" range="-2.41 2.41" armature="2.5" damping="0.1" frictionloss="0.1"/>
          <geom name="robot0_ha1_visual" type="mesh" contype="0" conaffinity="0" group="1" rgba="1 1 1 1" mesh="robot0_half_arm_1_link"/>
          <geom name="robot0_ha1_collision" type="mesh" conaffinity="0" rgba="0 0.5 0 1" mesh="robot0_half_arm_1_link"/>
          <body name="robot0_HalfArm2_Link" pos="0 -0.21038 -0.006375" quat="0.707105 -0.707108 0 0">
            <inertial pos="-4.4e-05 -0.006641 -0.117892" quat="0.706144 0.0213722 -0.0209128 0.707437" mass="1.1636" diaginertia="0.0111633 0.010932 0.00100671"/>
            <joint name="robot0_Actuator3" pos="0 0 0" axis="0 0 1" armature="1.66667" damping="0.1" frictionloss="0.1"/>
            <geom name="robot0_ha2_visual" type="mesh" contype="0" conaffinity="0" group="1" rgba="1 1 1 1" mesh="robot0_half_arm_2_link"/>
            <geom name="robot0_ha2_collision" type="mesh" conaffinity="0" rgba="0 0.5 0 1" mesh="robot0_half_arm_2_link"/>
            <body name="robot0_forearm_link" pos="0 0.006375 -0.21038" quat="0.707105 0.707108 0 0">
              <inertial pos="-1.8e-05 -0.075478 -0.015006" quat="0.483678 0.515961 -0.515859 0.483455" mass="0.9302" diaginertia="0.00834839 0.008147 0.000598606"/>
              <joint name="robot0_Actuator4" pos="0 0 0" axis="0 0 1" range="-2.66 2.66" armature="1.25" damping="0.1" frictionloss="0.1"/>
              <geom name="robot0_f_visual" type="mesh" contype="0" conaffinity="0" group="1" rgba="1 1 1 1" mesh="robot0_forearm_link"/>
              <geom name="robot0_f_collision" type="mesh" conaffinity="0" rgba="0 0.5 0 1" mesh="robot0_forearm_link"/>
              <body name="robot0_SphericalWrist1_Link" pos="0 -0.20843 -0.006375" quat="0.707105 -0.707108 0 0">
                <inertial pos="1e-06 -0.009432 -0.063883" quat="0.703558 0.0707492 -0.0707492 0.703558" mass="0.6781" diaginertia="0.00165901 0.001596 0.000346988"/>
                <joint name="robot0_Actuator5" pos="0 0 0" axis="0 0 1" armature="1" damping="0.1" frictionloss="0.1"/>
                <geom name="robot0_w1_visual" type="mesh" contype="0" conaffinity="0" group="1" rgba="1 1 1 1" mesh="robot0_spherical_wrist_1_link"/>
                <geom name="robot0_w1_collision" type="mesh" conaffinity="0" rgba="0 0.5 0 1" mesh="robot0_spherical_wrist_1_link"/>
                <body name="robot0_SphericalWrist2_Link" pos="0 0.00017505 -0.10593" quat="0.707105 0.707108 0 0">
                  <inertial pos="1e-06 -0.045483 -0.00965" quat="0.44426 0.550121 -0.550121 0.44426" mass="0.6781" diaginertia="0.00170087 0.001641 0.00035013"/>
                  <joint name="robot0_Actuator6" pos="0 0 0" axis="0 0 1" range="-2.23 2.23" armature="0.833333" damping="0.01" frictionloss="0.1"/>
                  <geom name="robot0_w2_visual" type="mesh" contype="0" conaffinity="0" group="1" rgba="1 1 1 1" mesh="robot0_spherical_wrist_2_link"/>
                  <geom name="robot0_w2_collision" type="mesh" conaffinity="0" rgba="0 0.5 0 1" mesh="robot0_spherical_wrist_2_link"/>
                  <body name="robot0_Bracelet_Link" pos="0 -0.10593 -0.00017505" quat="0.707105 -0.707108 0 0">
                    <inertial pos="-0.000281 -0.011402 -0.029798" quat="0.601961 0.40663 -0.381169 0.571843" mass="0.5006" diaginertia="0.000657515 0.000586793 0.000320693"/>
                    <joint name="robot0_Actuator7" pos="0 0 0" axis="0 0 1" armature="0.714286" damping="0.01" frictionloss="0.1"/>
                    <geom name="robot0_b_visual" type="mesh" contype="0" conaffinity="0" group="1" rgba="1 1 1 1" mesh="robot0_bracelet_with_vision_link"/>
                    <geom name="robot0_b_collision" type="mesh" conaffinity="0" rgba="0 0.5 0 1" mesh="robot0_bracelet_with_vision_link"/>
                    <body name="robot0_right_hand" pos="0 0 -0.065" quat="0 0.707105 -0.707108 0">
                      <camera name="robot0_eye_in_hand" pos="0.05 0 0" quat="0 0.707107 0.707107 0" fovy="75"/>
                      <body name="gripper0_robotiq_85_adapter_link">
                        <inertial pos="0 0 0" mass="0.01" diaginertia="0.001 0.001 0.001"/>
                        <geom name="gripper0_hand_visual" type="mesh" contype="0" conaffinity="0" group="1" rgba="0.1 0.1 0.1 1" mesh="gripper0_robotiq_arg2f_base_link"/>
                        <geom name="gripper0_hand_collision" type="mesh" rgba="0 0 0.5 1" mesh="gripper0_robotiq_arg2f_base_link"/>
                        <site name="gripper0_ft_frame" pos="0 0 0" size="0.01" group="1" rgba="1 0 0 -1"/>
                        <body name="gripper0_eef" pos="0 0 0.145" quat="0.707107 0 0 -0.707107">
                          <site name="gripper0_grip_site" pos="0 0 0" size="0.01" group="1" rgba="1 0 0 -0.5"/>
                          <site name="gripper0_ee_x" pos="0.1 0 0" quat="0.707105 0 0.707108 0" size="0.005 0.1" group="1" type="cylinder" rgba="1 0 0 0"/>
                          <site name="gripper0_ee_y" pos="0 0.1 0" quat="0.707105 0.707108 0 0" size="0.005 0.1" group="1" type="cylinder" rgba="0 1 0 0"/>
                          <site name="gripper0_ee_z" pos="0 0 0.1" size="0.005 0.1" group="1" type="cylinder" rgba="0 0 1 0"/>
                          <site name="gripper0_grip_site_cylinder" pos="0 0 0" size="0.005 10" group="1" type="cylinder" rgba="0 1 0 -0.3"/>
                        </body>
                        <body name="gripper0_left_outer_knuckle" pos="0 -0.0306011 0.054904" quat="0 0 0 1">
                          <inertial pos="0.000163875 0.0554825 -0.0100755" quat="0.920541 0.390623 -0.00362953 0.00231744" mass="0.0311462" diaginertia="5.11372e-05 4.89464e-05 4.95906e-06"/>
                          <joint name="gripper0_finger_joint" pos="0 0 0" axis="1 0 0" range="0 0.8"/>
                          <geom name="gripper0_left_outer_knuckle_visual" type="mesh" contype="0" conaffinity="0" group="1" rgba="0.792157 0.819608 0.933333 1" mesh="gripper0_robotiq_arg2f_85_outer_knuckle_vis"/>
                          <geom name="gripper0_left_outer_knuckle_collision" type="mesh" solref="0.01 0.25" rgba="0 0 0.5 1" mesh="gripper0_robotiq_arg2f_85_outer_knuckle"/>
                          <geom name="gripper0_left_outer_finger_visual" pos="0 0.0315 -0.0041" type="mesh" contype="0" conaffinity="0" group="1" rgba="0.1 0.1 0.1 1" mesh="gripper0_robotiq_arg2f_85_outer_finger_vis"/>
                          <geom name="gripper0_left_outer_finger_collision" pos="0 0.0315 -0.0041" type="mesh" solref="0.01 0.25" rgba="0 0 0.5 1" mesh="gripper0_robotiq_arg2f_85_outer_finger"/>
                          <body name="gripper0_left_inner_finger" pos="0 0.0376 0.043">
                            <inertial pos="0.000199506 0.0032692 0.00175282" quat="0.933621 0.35825 -0.00273441 0.00104851" mass="0.0156391" diaginertia="1.57977e-05 1.51089e-05 1.4647e-06"/>
                            <joint name="gripper0_left_inner_finger_joint" pos="0 0 0" axis="1 0 0" range="-0.8757 0.8757"/>
                            <geom name="gripper0_left_inner_finger_visual" type="mesh" contype="0" conaffinity="0" group="1" rgba="0.1 0.1 0.1 1" mesh="gripper0_robotiq_arg2f_85_inner_finger_vis"/>
                            <geom name="gripper0_left_inner_finger_collision" type="mesh" solref="0.01 0.25" rgba="0 0 0.5 1" mesh="gripper0_robotiq_arg2f_85_inner_finger"/>
                            <geom name="gripper0_left_fingertip_visual" size="0.011 0.003175 0.01875" pos="0 -0.0220203 0.03242" type="box" contype="0" conaffinity="0" group="1" rgba="0.9 0.9 0.9 1"/>
                            <geom name="gripper0_left_fingertip_collision" size="0.011 0.003175 0.01875" pos="0 -0.0220203 0.03242" type="box" solref="0.01 0.25" rgba="0 0 0.5 1"/>
                            <geom name="gripper0_left_fingerpad_collision" size="0.01 0.001 0.01675" pos="0 -0.0245203 0.03242" type="box" rgba="0 0 0.5 1"/>
                          </body>
                        </body>
                        <body name="gripper0_left_inner_knuckle" pos="0 -0.0127 0.06142" quat="0 0 0 1">
                          <inertial pos="0.000123012 0.0507851 0.00103969" quat="0.497203 0.502496 -0.507943 0.492221" mass="0.0271177" diaginertia="2.83809e-05 2.61936e-05 2.81319e-06"/>
                          <joint name="gripper0_left_inner_knuckle_joint" pos="0 0 0" axis="1 0 0" range="0 0.8757"/>
                          <geom name="gripper0_left_inner_knuckle_visual" type="mesh" contype="0" conaffinity="0" group="1" rgba="0.1 0.1 0.1 1" mesh="gripper0_robotiq_arg2f_85_inner_knuckle_vis"/>
                          <geom name="gripper0_left_inner_knuckle_collision" type="mesh" rgba="0 0 0.5 1" mesh="gripper0_robotiq_arg2f_85_inner_knuckle"/>
                        </body>
                        <body name="gripper0_right_outer_knuckle" pos="0 0.0306011 0.054904">
                          <inertial pos="0.000163875 0.0554825 -0.0100755" quat="0.920541 0.390623 -0.00362953 0.00231744" mass="0.0311462" diaginertia="5.11372e-05 4.89464e-05 4.95906e-06"/>
                          <joint name="gripper0_right_outer_knuckle_joint" pos="0 0 0" axis="1 0 0" range="0 0.8"/>
                          <geom name="gripper0_right_outer_knuckle_visual" type="mesh" contype="0" conaffinity="0" group="1" rgba="0.792157 0.819608 0.933333 1" mesh="gripper0_robotiq_arg2f_85_outer_knuckle_vis"/>
                          <geom name="gripper0_right_outer_knuckle_collision" type="mesh" solref="0.01 0.25" rgba="0 0 0.5 1" mesh="gripper0_robotiq_arg2f_85_outer_knuckle"/>
                          <geom name="gripper0_right_outer_finger_visual" pos="0 0.0315 -0.0041" type="mesh" contype="0" conaffinity="0" group="1" rgba="0.1 0.1 0.1 1" mesh="gripper0_robotiq_arg2f_85_outer_finger_vis"/>
                          <geom name="gripper0_right_outer_finger_collision" pos="0 0.0315 -0.0041" type="mesh" solref="0.01 0.25" rgba="0 0 0.5 1" mesh="gripper0_robotiq_arg2f_85_outer_finger"/>
                          <body name="gripper0_right_inner_finger" pos="0 0.0376 0.043">
                            <inertial pos="0.000199506 0.0032692 0.00175282" quat="0.933621 0.35825 -0.00273441 0.00104851" mass="0.0156391" diaginertia="1.57977e-05 1.51089e-05 1.4647e-06"/>
                            <joint name="gripper0_right_inner_finger_joint" pos="0 0 0" axis="1 0 0" range="-0.8757 0.8757"/>
                            <geom name="gripper0_right_inner_finger_visual" type="mesh" contype="0" conaffinity="0" group="1" rgba="0.1 0.1 0.1 1" mesh="gripper0_robotiq_arg2f_85_inner_finger_vis"/>
                            <geom name="gripper0_right_inner_finger_collision" type="mesh" solref="0.01 0.25" rgba="0 0 0.5 1" mesh="gripper0_robotiq_arg2f_85_inner_finger"/>
                            <geom name="gripper0_right_fingertip_visual" size="0.011 0.003175 0.01875" pos="0 -0.0220203 0.03242" type="box" contype="0" conaffinity="0" group="1" rgba="0.9 0.9 0.9 1"/>
                            <geom name="gripper0_right_fingertip_collision" size="0.011 0.003175 0.01875" pos="0 -0.0220203 0.03242" type="box" solref="0.01 0.25" rgba="0 0 0.5 1"/>
                            <geom name="gripper0_right_fingerpad_collision" size="0.01 0.001 0.01675" pos="0 -0.0245203 0.03242" type="box" rgba="0 0 0.5 1"/>
                          </body>
                        </body>
                        <body name="gripper0_right_inner_knuckle" pos="0 0.0127 0.06142">
                          <inertial pos="0.000123012 0.0507851 0.00103969" quat="0.497203 0.502496 -0.507943 0.492221" mass="0.0271177" diaginertia="2.83809e-05 2.61936e-05 2.81319e-06"/>
                          <joint name="gripper0_right_inner_knuckle_joint" pos="0 0 0" axis="1 0 0" range="0 0.8757"/>
                          <geom name="gripper0_right_inner_knuckle_visual" type="mesh" contype="0" conaffinity="0" group="1" rgba="0.1 0.1 0.1 1" mesh="gripper0_robotiq_arg2f_85_inner_knuckle_vis"/>
                          <geom name="gripper0_right_inner_knuckle_collision" type="mesh" rgba="0 0 0.5 1" mesh="gripper0_robotiq_arg2f_85_inner_knuckle"/>
                        </body>
                      </body>
                    </body>
                  </body>
                </body>
              </body>
            </body>
          </body>
        </body>
      </body>
      <body name="mount0_base" pos="0 0 0.01">
        <body name="mount0_controller_box">
          <inertial pos="-0.325 0 -0.38" mass="46.64" diaginertia="1.71363 1.27988 0.809981"/>
          <geom name="mount0_controller_box_col" size="0.11 0.2 0.265" pos="-0.325 0 -0.38" type="box" rgba="0.5 0.5 0 1"/>
        </body>
        <body name="mount0_pedestal_feet">
          <inertial pos="-0.1225 0 -0.758" mass="167.09" diaginertia="8.16095 9.59375 15.0785"/>
          <geom name="mount0_pedestal_feet_col" size="0.385 0.35 0.155" pos="-0.1225 0 -0.758" type="box" rgba="0.5 0.5 0 1"/>
        </body>
        <body name="mount0_torso">
          <inertial pos="0 0 0" mass="0.0001" diaginertia="1e-08 1e-08 1e-08"/>
          <geom name="mount0_torso_vis" size="0.05 0.05 0.05" pos="0 0 -0.05" type="box" contype="0" conaffinity="0" group="1" rgba="0.2 0.2 0.2 1"/>
        </body>
        <body name="mount0_pedestal">
          <inertial pos="0 0 0" quat="0.659267 -0.259505 -0.260945 0.655692" mass="60.864" diaginertia="6.0869 5.81635 4.20915"/>
          <geom name="mount0_pedestal_vis" type="mesh" contype="0" conaffinity="0" group="1" rgba="0.2 0.2 0.2 1" mesh="mount0_pedestal"/>
          <geom name="mount0_pedestal_col" size="0.18 0.31" pos="-0.02 0 -0.29" type="cylinder" rgba="0.5 0.5 0 1"/>
        </body>
      </body>
    </body>
    <body name="cube_bread_main">
      <joint name="cube_bread_joint0" type="free"/>
      <geom name="cube_bread_g0" size="0.015 0.025 0.02" type="box" density="500" rgba="0.5 0 0 1"/>
      <geom name="cube_bread_g0_vis" size="0.015 0.025 0.02" type="box" contype="0" conaffinity="0" group="1" mass="0" material="cube_bread_MatBread"/>
      <site name="cube_bread_default_site" pos="0 0 0" size="0.002" rgba="1 0 0 -1"/>
    </body>
    <body name="PotObject_root">
      <joint name="PotObject_joint0" type="free" damping="0.0005"/>
      <geom name="PotObject_body_0" size="0.043 0.053 0.005" pos="0 0 0.0025" type="box" friction="0.0005 0.005 0.0001" rgba="0.5 0 0 1"/>
      <geom name="PotObject_body_0_vis" size="0.043 0.053 0.005" pos="0 0 0.0025" type="box" contype="0" conaffinity="0" group="1" mass="0" material="PotObject_steel_scratched_mat"/>
      <geom name="PotObject_body_1" size="0.057 0.007 0.035" pos="0 -0.06 0.0325" type="box" friction="0.005 0.005 0.0001" rgba="0.5 0 0 1"/>
      <geom name="PotObject_body_1_vis" size="0.057 0.007 0.035" pos="0 -0.06 0.0325" type="box" contype="0" conaffinity="0" group="1" mass="0" material="PotObject_steel_scratched_mat"/>
      <geom name="PotObject_body_2" size="0.057 0.007 0.035" pos="0 0.06 0.0325" type="box" friction="0.005 0.005 0.0001" rgba="0.5 0 0 1"/>
      <geom name="PotObject_body_2_vis" size="0.057 0.007 0.035" pos="0 0.06 0.0325" type="box" contype="0" conaffinity="0" group="1" mass="0" material="PotObject_steel_scratched_mat"/>
      <geom name="PotObject_body_3" size="0.007 0.053 0.035" pos="0.05 0 0.0325" type="box" friction="0.005 0.005 0.0001" rgba="0.5 0 0 1"/>
      <geom name="PotObject_body_3_vis" size="0.007 0.053 0.035" pos="0.05 0 0.0325" type="box" contype="0" conaffinity="0" group="1" mass="0" material="PotObject_steel_scratched_mat"/>
      <geom name="PotObject_body_4" size="0.007 0.053 0.035" pos="-0.05 0 0.0325" type="box" friction="0.005 0.005 0.0001" rgba="0.5 0 0 1"/>
      <geom name="PotObject_body_4_vis" size="0.007 0.053 0.035" pos="-0.05 0 0.0325" type="box" contype="0" conaffinity="0" group="1" mass="0" material="PotObject_steel_scratched_mat"/>
      <geom name="PotObject_handle_left_1" size="0.0275 0.007 0.01" pos="0 0.06 0.077" type="box" friction="0.005 0.005 0.0001" rgba="0.5 0 0 1"/>
      <geom name="PotObject_handle_left_1_vis" size="0.0275 0.007 0.01" pos="0 0.06 0.077" type="box" contype="0" conaffinity="0" group="1" mass="0" material="PotObject_steel_scratched_mat"/>
      <geom name="PotObject_handle_right_1" size="0.0275 0.007 0.01" pos="0 -0.06 0.077" type="box" friction="0.005 0.005 0.0001" rgba="0.5 0 0 1"/>
      <geom name="PotObject_handle_right_1_vis" size="0.0275 0.007 0.01" pos="0 -0.06 0.077" type="box" contype="0" conaffinity="0" group="1" mass="0" material="PotObject_steel_scratched_mat"/>
      <site name="PotObject_default_site" pos="0 0 0" size="0.002" rgba="1 0 0 0"/>
    </body>
  </worldbody>
  <tendon>
    <fixed name="gripper0_finger2_12_cpl" range="-1 1" stiffness="0.4" springlength="0.001">
      <joint joint="gripper0_finger_joint" coef="1"/>
      <joint joint="gripper0_left_inner_finger_joint" coef="-3"/>
      <joint joint="gripper0_left_inner_knuckle_joint" coef="1"/>
    </fixed>
    <fixed name="gripper0_finger1_12_cpl" range="-1 1" stiffness="0.4" springlength="0.001">
      <joint joint="gripper0_right_outer_knuckle_joint" coef="1"/>
      <joint joint="gripper0_right_inner_finger_joint" coef="-3"/>
      <joint joint="gripper0_right_inner_knuckle_joint" coef="1"/>
    </fixed>
  </tendon>
  <actuator>
    <general name="robot0_torq_j1" joint="robot0_Actuator1" ctrlrange="-32 32"/>
    <general name="robot0_torq_j2" joint="robot0_Actuator2" ctrlrange="-32 32"/>
    <general name="robot0_torq_j3" joint="robot0_Actuator3" ctrlrange="-32 32"/>
    <general name="robot0_torq_j4" joint="robot0_Actuator4" ctrlrange="-32 32"/>
    <general name="robot0_torq_j5" joint="robot0_Actuator5" ctrlrange="-32 32"/>
    <general name="robot0_torq_j6" joint="robot0_Actuator6" ctrlrange="-13 13"/>
    <general name="robot0_torq_j7" joint="robot0_Actuator7" ctrlrange="-13 13"/>
    <general name="gripper0_finger_1" joint="gripper0_finger_joint" ctrlrange="0 0.8" biastype="affine" gainprm="20 0 0 0 0 0 0 0 0 0" biasprm="0 -20 0 0 0 0 0 0 0 0"/>
    <general name="gripper0_finger_2" joint="gripper0_right_outer_knuckle_joint" ctrlrange="0 0.8" biastype="affine" gainprm="20 0 0 0 0 0 0 0 0 0" biasprm="0 -20 0 0 0 0 0 0 0 0"/>
  </actuator>
  <sensor>
    <force site="gripper0_ft_frame" name="gripper0_force_ee"/>
    <torque site="gripper0_ft_frame" name="gripper0_torque_ee"/>
  </sensor>
</mujoco>
